I'm sorry, but an uncaught exception occurred.

While running game code:
  File "game/script.rpy", line 144, in script
    unknown "啊啊啊有鬼啊！"
Exception: Sayer 'unknown' is not defined.

-- Full Traceback ------------------------------------------------------------

Full traceback:
  File "game/script.rpy", line 144, in script
    unknown "啊啊啊有鬼啊！"
  File "/usr/share/renpy/renpy/ast.py", line 890, in execute
    who = eval_who(self.who, self.who_fast)
  File "/usr/share/renpy/renpy/ast.py", line 783, in eval_who
    raise Exception("Sayer '%s' is not defined." % who)
Exception: Sayer 'unknown' is not defined.

Linux-6.5.5-arch1-1-x86_64-with-glibc2.38 x86_64
Ren'Py 8.2.0.0+unofficial
運命のささやき: 私のそばに降り立つ星空ニャン 1.0
Wed Nov 29 20:45:21 2023
